Workbook

Sheet Dashboard
A1: Fresh Produce Supply Chain Analytics: Demand Forecasting, Inventory Optimization & Waste Reduction
A2: Manager dashboard | Period: 1–30 Sep 2026 | Practice project on simulated data (not actual Fambo data)
A4: TOTAL DEMAND | D4: FORECAST – NEXT 7 DAYS | G4: TOTAL WASTE | J4: WASTE % OF DEMAND | M4: AVERAGE FILL RATE | P4: STOCKOUT DAYS
A5: =SUM(Data!$D$2:$D$151) -> 8479 | D5: =Demand!E10 -> 2000 | G5: =SUM(Data!$K$2:$K$151) -> 1755 | J5: =Waste!D14 -> 0.20698196 | M5: =AVERAGE(Data!$L$2:$L$151) -> 1 | P5: =SUM(Data!$P$2:$P$151) -> 0
A7: kg in 30 days | D7: kg expected demand | G7: kg expired / written off | J7: too high – main problem | M7: demand fully served | P7: days demand was missed
A9: THE 3 BUSINESS QUESTIONS – ANSWERED FROM THE DATA
A10: 1 WHAT TO ORDER? | G10: 2 WHEN TO ORDER? | M10: 3 HOW TO REDUCE WASTE?
A11: ="Plan for about "&TEXT(Demand!E10,"#,##0")&" kg over the next 7 days. "&INDEX(Demand!A5:A9,MATCH(MAX(Demand!E5:E9),Demand!E5:E9,0))&" needs the most ("&TEXT(MAX(Demand!E5:E9),"#,##0")&" kg). In each "&Inventory!B4&"-day order cycle, order about "&TEXT(Inventory!N14,"#,##0")&" kg in total – product-wise quantities are in the scorecard below." -> Plan for about 2,000 kg over the next 7 days. Potato needs the most (546 kg). In each 4-day order cycle, order about 1,160 kg in total – product-wise quantities are in the scorecard below. | G11: ="Order when stock falls to the reorder point. Right now "&COUNTIF(Inventory!K9:K13,"ORDER NOW")&" product(s) need an order and "&COUNTIF(Inventory!K9:K13,"WATCH")&" are on watch. Next order is due for "&INDEX(Inventory!A9:A13,MATCH(MIN(Inventory!L9:L13),Inventory!L9:L13,0))&IF(MIN(Inventory!L9:L13)<0.5," right now."," in about "&TEXT(MIN(Inventory!L9:L13),"0.0")&" day(s).") -> Order when stock falls to the reorder point. Right now 1 product(s) need an order and 0 are on watch. Next order is due for Capsicum right now. | M11: ="Waste is "&TEXT(Waste!D14,"0.0%")&" of demand ("&TEXT(Waste!C14,"#,##0")&" kg) while fill rate is "&TEXT(AVERAGE(Data!$L$2:$L$151),"0%")&" – so we hold too much stock. "&INDEX(Waste!A9:A13,MATCH(MAX(Waste!C9:C13),Waste!C9:C13,0))&" loses the most. Use FEFO, order smaller batches, and cut waste by "&TEXT(Waste!B3,"0%")&" to save about "&TEXT(Waste!J14,"#,##0")&" kg." -> Waste is 20.7% of demand (1,755 kg) while fill rate is 100% – so we hold too much stock. Onion loses the most. Use FEFO, order smaller batches, and cut waste by 50% to save about 878 kg.
A15: 1 · DEMAND & FORECAST
A32: 2 · INVENTORY & REORDER POINT
A33: Pick a product for the stock chart ▶ | D33: Tomato | F33: (click the yellow cell and choose from the dropdown)
A50: 3 · WASTE & EXPIRY
A67: PRODUCT SCORECARD
A68: Product | B68: Demand (kg) | C68: Avg demand / day (kg) | D68: Forecast next 7 days (kg) | E68: Forecast accuracy | F68: Reorder point (kg) | G68: Stock now (kg) | H68: Days of cover | I68: Stock status | J68: Suggested order qty (kg) | K68: Next order date | L68: Waste (kg) | M68: Waste % of demand | N68: Fill rate | O68: Stockout days | P68: Excess stock (kg) | Q68: Est. waste value (₹) | R68: Avg stock held (kg)
A69: =Inventory!A9 -> Tomato | B69: =Waste!B9 -> 1817 | C69: =Inventory!B9 -> 60.566667 | D69: =Demand!E5 -> 449 | E69: =Demand!I5 -> 0.83483838 | F69: =Inventory!G9 -> 211 | G69: =Inventory!I9 -> 349 | H69: =Inventory!J9 -> 5.7622455 | I69: =Inventory!K9 -> OK | J69: =Inventory!N9 -> 250 | K69: =Inventory!M9 -> 46297 | L69: =Waste!C9 -> 374 | M69: =Waste!D9 -> 0.20583379 | N69: =Inventory!S9 -> 1 | O69: =Inventory!R9 -> 0 | P69: =Inventory!Q9 -> 163.9 | Q69: =Waste!I9 -> 9350 | R69: =Inventory!O9 -> 317.9
A70: =Inventory!A10 -> Onion | B70: =Waste!B10 -> 2184 | C70: =Inventory!B10 -> 72.8 | D70: =Demand!E6 -> 503 | E70: =Demand!I6 -> 0.86155293 | F70: =Inventory!G10 -> 325 | G70: =Inventory!I10 -> 584 | H70: =Inventory!J10 -> 8.021978 | I70: =Inventory!K10 -> OK | J70: =Inventory!N10 -> 300 | K70: =Inventory!M10 -> 46298 | L70: =Waste!C10 -> 485 | M70: =Waste!D10 -> 0.2220696 | N70: =Inventory!S10 -> 1 | O70: =Inventory!R10 -> 0 | P70: =Inventory!Q10 -> 316.83333 | Q70: =Waste!I10 -> 14550 | R70: =Inventory!O10 -> 500.83333
A71: =Inventory!A11 -> Potato | B71: =Waste!B11 -> 2371 | C71: =Inventory!B11 -> 79.033333 | D71: =Demand!E7 -> 546 | E71: =Demand!I7 -> 0.80765734 | F71: =Inventory!G11 -> 363 | G71: =Inventory!I11 -> 745 | H71: =Inventory!J11 -> 9.4264024 | I71: =Inventory!K11 -> OK | J71: =Inventory!N11 -> 320 | K71: =Inventory!M11 -> 46299 | L71: =Waste!C11 -> 461 | M71: =Waste!D11 -> 0.19443273 | N71: =Inventory!S11 -> 1 | O71: =Inventory!R11 -> 0 | P71: =Inventory!Q11 -> 343.16667 | Q71: =Waste!I11 -> 10142 | R71: =Inventory!O11 -> 550.16667
A72: =Inventory!A12 -> Cucumber | B72: =Waste!B12 -> 1187 | C72: =Inventory!B12 -> 39.566667 | D72: =Demand!E8 -> 307 | E72: =Demand!I8 -> 0.84652199 | F72: =Inventory!G12 -> 95 | G72: =Inventory!I12 -> 129 | H72: =Inventory!J12 -> 3.2603201 | I72: =Inventory!K12 -> OK | J72: =Inventory!N12 -> 160 | K72: =Inventory!M12 -> 46295 | L72: =Waste!C12 -> 239 | M72: =Waste!D12 -> 0.20134794 | N72: =Inventory!S12 -> 1 | O72: =Inventory!R12 -> 0 | P72: =Inventory!Q12 -> 44.1 | Q72: =Waste!I12 -> 6692 | R72: =Inventory!O12 -> 140.1
A73: =Inventory!A13 -> Capsicum | B73: =Waste!B13 -> 920 | C73: =Inventory!B13 -> 30.666667 | D73: =Demand!E9 -> 195 | E73: =Demand!I9 -> 0.83446325 | F73: =Inventory!G13 -> 106 | G73: =Inventory!I13 -> 87 | H73: =Inventory!J13 -> 2.8369565 | I73: =Inventory!K13 -> ORDER NOW | J73: =Inventory!N13 -> 130 | K73: =Inventory!M13 -> 46295 | L73: =Waste!C13 -> 196 | M73: =Waste!D13 -> 0.21304348 | N73: =Inventory!S13 -> 1 | O73: =Inventory!R13 -> 0 | P73: =Inventory!Q13 -> 81.8 | Q73: =Waste!I13 -> 8820 | R73: =Inventory!O13 -> 160.8
A74: Total | B74: =SUM(B69:B73) -> 8479 | C74: =SUM(C69:C73) -> 282.63333 | D74: =SUM(D69:D73) -> 2000 | E74: =Demand!I10 -> 0.92563827 | F74: =SUM(F69:F73) -> 1100 | G74: =SUM(G69:G73) -> 1894 | H74: =G74/C74 -> 6.7012619 | J74: =SUM(J69:J73) -> 1160 | L74: =SUM(L69:L73) -> 1755 | M74: =L74/B74 -> 0.20698196 | N74: =AVERAGE(N69:N73) -> 1 | O74: =SUM(O69:O73) -> 0 | P74: =SUM(P69:P73) -> 949.8 | Q74: =SUM(Q69:Q73) -> 49554 | R74: =SUM(R69:R73) -> 1669.8
A76: Method: forecast = 7-day moving average · safety stock = Z × std. dev. × √lead time (95% service level) · reorder point = avg demand × lead time + safety stock · prices used for waste value are assumptions. See the ReadMe tab.

Sheet Demand
A1: 1 · Demand Analysis & Forecast
A2: Forecast method: average of the previous 7 days (simple moving average). Accuracy is checked by testing the method on the past 23 days.
A3: Forecast summary (kg)
A4: Product | B4: Avg demand / day (30 days) | C4: Last 7-day avg / day | D4: Trend vs 30-day avg | E4: Forecast next 7 days (kg) | F4: Forecast next 14 days (kg) | G4: Peak day demand (kg) | H4: Forecast error (MAPE) | I4: Forecast accuracy
A5: Tomato | B5: =AVERAGE(INDEX($B$15:$F$44,0,MATCH($A5,$B$14:$F$14,0))) -> 60.566667 | C5: =AVERAGE(INDEX($B$38:$F$44,0,MATCH($A5,$B$14:$F$14,0))) -> 64.142857 | D5: =C5/B5-1 -> 0.059045522 | E5: =C5*7 -> 449 | F5: =C5*14 -> 898 | G5: =MAX(INDEX($B$15:$F$44,0,MATCH($A5,$B$14:$F$14,0))) -> 76 | H5: =SUMPRODUCT(ABS(INDEX($B$22:$F$44,0,MATCH($A5,$B$14:$F$14,0))-INDEX($J$22:$N$44,0,MATCH($A5,$B$14:$F$14,0)))/INDEX($B$22:$F$44,0,MATCH($A5,$B$14:$F$14,0)))/ROWS($B$22:$B$44) -> 0.16516162 | I5: =1-H5 -> 0.83483838
A6: Onion | B6: =AVERAGE(INDEX($B$15:$F$44,0,MATCH($A6,$B$14:$F$14,0))) -> 72.8 | C6: =AVERAGE(INDEX($B$38:$F$44,0,MATCH($A6,$B$14:$F$14,0))) -> 71.857143 | D6: =C6/B6-1 -> -0.012951334 | E6: =C6*7 -> 503 | F6: =C6*14 -> 1006 | G6: =MAX(INDEX($B$15:$F$44,0,MATCH($A6,$B$14:$F$14,0))) -> 91 | H6: =SUMPRODUCT(ABS(INDEX($B$22:$F$44,0,MATCH($A6,$B$14:$F$14,0))-INDEX($J$22:$N$44,0,MATCH($A6,$B$14:$F$14,0)))/INDEX($B$22:$F$44,0,MATCH($A6,$B$14:$F$14,0)))/ROWS($B$22:$B$44) -> 0.13844707 | I6: =1-H6 -> 0.86155293
A7: Potato | B7: =AVERAGE(INDEX($B$15:$F$44,0,MATCH($A7,$B$14:$F$14,0))) -> 79.033333 | C7: =AVERAGE(INDEX($B$38:$F$44,0,MATCH($A7,$B$14:$F$14,0))) -> 78 | D7: =C7/B7-1 -> -0.013074652 | E7: =C7*7 -> 546 | F7: =C7*14 -> 1092 | G7: =MAX(INDEX($B$15:$F$44,0,MATCH($A7,$B$14:$F$14,0))) -> 104 | H7: =SUMPRODUCT(ABS(INDEX($B$22:$F$44,0,MATCH($A7,$B$14:$F$14,0))-INDEX($J$22:$N$44,0,MATCH($A7,$B$14:$F$14,0)))/INDEX($B$22:$F$44,0,MATCH($A7,$B$14:$F$14,0)))/ROWS($B$22:$B$44) -> 0.19234266 | I7: =1-H7 -> 0.80765734
A8: Cucumber | B8: =AVERAGE(INDEX($B$15:$F$44,0,MATCH($A8,$B$14:$F$14,0))) -> 39.566667 | C8: =AVERAGE(INDEX($B$38:$F$44,0,MATCH($A8,$B$14:$F$14,0))) -> 43.857143 | D8: =C8/B8-1 -> 0.10843663 | E8: =C8*7 -> 307 | F8: =C8*14 -> 614 | G8: =MAX(INDEX($B$15:$F$44,0,MATCH($A8,$B$14:$F$14,0))) -> 50 | H8: =SUMPRODUCT(ABS(INDEX($B$22:$F$44,0,MATCH($A8,$B$14:$F$14,0))-INDEX($J$22:$N$44,0,MATCH($A8,$B$14:$F$14,0)))/INDEX($B$22:$F$44,0,MATCH($A8,$B$14:$F$14,0)))/ROWS($B$22:$B$44) -> 0.15347801 | I8: =1-H8 -> 0.84652199
A9: Capsicum | B9: =AVERAGE(INDEX($B$15:$F$44,0,MATCH($A9,$B$14:$F$14,0))) -> 30.666667 | C9: =AVERAGE(INDEX($B$38:$F$44,0,MATCH($A9,$B$14:$F$14,0))) -> 27.857143 | D9: =C9/B9-1 -> -0.091614907 | E9: =C9*7 -> 195 | F9: =C9*14 -> 390 | G9: =MAX(INDEX($B$15:$F$44,0,MATCH($A9,$B$14:$F$14,0))) -> 39 | H9: =SUMPRODUCT(ABS(INDEX($B$22:$F$44,0,MATCH($A9,$B$14:$F$14,0))-INDEX($J$22:$N$44,0,MATCH($A9,$B$14:$F$14,0)))/INDEX($B$22:$F$44,0,MATCH($A9,$B$14:$F$14,0)))/ROWS($B$22:$B$44) -> 0.16553675 | I9: =1-H9 -> 0.83446325
A10: Total | B10: =SUM(B5:B9) -> 282.63333 | C10: =SUM(C5:C9) -> 285.71429 | D10: =C10/B10-1 -> 0.010900881 | E10: =SUM(E5:E9) -> 2000 | F10: =SUM(F5:F9) -> 4000 | G10: =MAX(G15:G44) -> 333 | H10: =SUMPRODUCT(ABS(G22:G44-H22:H44)/G22:G44)/ROWS(G22:G44) -> 0.074361732 | I10: =1-H10 -> 0.92563827
A11: MAPE = average % gap between forecast and actual demand (lower is better). Accuracy = 1 - MAPE.
A13: Daily demand (kg) and forecast
A14: Date | B14: Tomato | C14: Onion | D14: Potato | E14: Cucumber | F14: Capsicum | G14: Total actual (kg) | H14: Total forecast (kg) | J14: Tomato forecast | K14: Onion forecast | L14: Potato forecast | M14: Cucumber forecast | N14: Capsicum forecast
A15: =MIN(Data!$A$2:$A$151) -> 46266 | B15: =SUMIFS(Data!$D$2:$D$151,Data!$B$2:$B$151,B$14,Data!$A$2:$A$151,$A15) -> 48 | C15: =SUMIFS(Data!$D$2:$D$151,Data!$B$2:$B$151,C$14,Data!$A$2:$A$151,$A15) -> 80 | D15: =SUMIFS(Data!$D$2:$D$151,Data!$B$2:$B$151,D$14,Data!$A$2:$A$151,$A15) -> 74 | E15: =SUMIFS(Data!$D$2:$D$151,Data!$B$2:$B$151,E$14,Data!$A$2:$A$151,$A15) -> 32 | F15: =SUMIFS(Data!$D$2:$D$151,Data!$B$2:$B$151,F$14,Data!$A$2:$A$151,$A15) -> 30 | G15: =SUM(B15:F15) -> 264
A16: =A15+1 -> 46267 | B16: =SUMIFS(Data!$D$2:$D$151,Data!$B$2:$B$151,B$14,Data!$A$2:$A$151,$A16) -> 59 | C16: =SUMIFS(Data!$D$2:$D$151,Data!$B$2:$B$151,C$14,Data!$A$2:$A$151,$A16) -> 73 | D16: =SUMIFS(Data!$D$2:$D$151,Data!$B$2:$B$151,D$14,Data!$A$2:$A$151,$A16) -> 80 | E16: =SUMIFS(Data!$D$2:$D$151,Data!$B$2:$B$151,E$14,Data!$A$2:$A$151,$A16) -> 33 | F16: =SUMIFS(Data!$D$2:$D$151,Data!$B$2:$B$151,F$14,Data!$A$2:$A$151,$A16) -> 26 | G16: =SUM(B16:F16) -> 271
A17: =A16+1 -> 46268 | B17: =SUMIFS(Data!$D$2:$D$151,Data!$B$2:$B$151,B$14,Data!$A$2:$A$151,$A17) -> 66 | C17: =SUMIFS(Data!$D$2:$D$151,Data!$B$2:$B$151,C$14,Data!$A$2:$A$151,$A17) -> 66 | D17: =SUMIFS(Data!$D$2:$D$151,Data!$B$2:$B$151,D$14,Data!$A$2:$A$151,$A17) -> 90 | E17: =SUMIFS(Data!$D$2:$D$151,Data!$B$2:$B$151,E$14,Data!$A$2:$A$151,$A17) -> 45 | F17: =SUMIFS(Data!$D$2:$D$151,Data!$B$2:$B$151,F$14,Data!$A$2:$A$151,$A17) -> 37 | G17: =SUM(B17:F17) -> 304
A18: =A17+1 -> 46269 | B18: =SUMIFS(Data!$D$2:$D$151,Data!$B$2:$B$151,B$14,Data!$A$2:$A$151,$A18) -> 75 | C18: =SUMIFS(Data!$D$2:$D$151,Data!$B$2:$B$151,C$14,Data!$A$2:$A$151,$A18) -> 62 | D18: =SUMIFS(Data!$D$2:$D$151,Data!$B$2:$B$151,D$14,Data!$A$2:$A$151,$A18) -> 69 | E18: =SUMIFS(Data!$D$2:$D$151,Data!$B$2:$B$151,E$14,Data!$A$2:$A$151,$A18) -> 44 | F18: =SUMIFS(Data!$D$2:$D$151,Data!$B$2:$B$151,F$14,Data!$A$2:$A$151,$A18) -> 32 | G18: =SUM(B18:F18) -> 282
A19: =A18+1 -> 46270 | B19: =SUMIFS(Data!$D$2:$D$151,Data!$B$2:$B$151,B$14,Data!$A$2:$A$151,$A19) -> 49 | C19: =SUMIFS(Data!$D$2:$D$151,Data!$B$2:$B$151,C$14,Data!$A$2:$A$151,$A19) -> 81 | D19: =SUMIFS(Data!$D$2:$D$151,Data!$B$2:$B$151,D$14,Data!$A$2:$A$151,$A19) -> 100 | E19: =SUMIFS(Data!$D$2:$D$151,Data!$B$2:$B$151,E$14,Data!$A$2:$A$151,$A19) -> 46 | F19: =SUMIFS(Data!$D$2:$D$151,Data!$B$2:$B$151,F$14,Data!$A$2:$A$151,$A19) -> 25 | G19: =SUM(B19:F19) -> 301
A20: =A19+1 -> 46271 | B20: =SUMIFS(Data!$D$2:$D$151,Data!$B$2:$B$151,B$14,Data!$A$2:$A$151,$A20) -> 52 | C20: =SUMIFS(Data!$D$2:$D$151,Data!$B$2:$B$151,C$14,Data!$A$2:$A$151,$A20) -> 52 | D20: =SUMIFS(Data!$D$2:$D$151,Data!$B$2:$B$151,D$14,Data!$A$2:$A$151,$A20) -> 104 | E20: =SUMIFS(Data!$D$2:$D$151,Data!$B$2:$B$151,E$14,Data!$A$2:$A$151,$A20) -> 32 | F20: =SUMIFS(Data!$D$2:$D$151,Data!$B$2:$B$151,F$14,Data!$A$2:$A$151,$A20) -> 35 | G20: =SUM(B20:F20) -> 275
A21: =A20+1 -> 46272 | B21: =SUMIFS(Data!$D$2:$D$151,Data!$B$2:$B$151,B$14,Data!$A$2:$A$151,$A21) -> 60 | C21: =SUMIFS(Data!$D$2:$D$151,Data!$B$2:$B$151,C$14,Data!$A$2:$A$151,$A21) -> 77 | D21: =SUMIFS(Data!$D$2:$D$151,Data!$B$2:$B$151,D$14,Data!$A$2:$A$151,$A21) -> 83 | E21: =SUMIFS(Data!$D$2:$D$151,Data!$B$2:$B$151,E$14,Data!$A$2:$A$151,$A21) -> 46 | F21: =SUMIFS(Data!$D$2:$D$151,Data!$B$2:$B$151,F$14,Data!$A$2:$A$151,$A21) -> 32 | G21: =SUM(B21:F21) -> 298
A22: =A21+1 -> 46273 | B22: =SUMIFS(Data!$D$2:$D$151,Data!$B$2:$B$151,B$14,Data!$A$2:$A$151,$A22) -> 52 | C22: =SUMIFS(Data!$D$2:$D$151,Data!$B$2:$B$151,C$14,Data!$A$2:$A$151,$A22) -> 57 | D22: =SUMIFS(Data!$D$2:$D$151,Data!$B$2:$B$151,D$14,Data!$A$2:$A$151,$A22) -> 81 | E22: =SUMIFS(Data!$D$2:$D$151,Data!$B$2:$B$151,E$14,Data!$A$2:$A$151,$A22) -> 48 | F22: =SUMIFS(Data!$D$2:$D$151,Data!$B$2:$B$151,F$14,Data!$A$2:$A$151,$A22) -> 24 | G22: =SUM(B22:F22) -> 262 | H22: =AVERAGE(G15:G21) -> 285 | J22: =AVERAGE(B15:B21) -> 58.428571 | K22: =AVERAGE(C15:C21) -> 70.142857 | L22: =AVERAGE(D15:D21) -> 85.714286 | M22: =AVERAGE(E15:E21) -> 39.714286 | N22: =AVERAGE(F15:F21) -> 31
A23: =A22+1 -> 46274 | B23: =SUMIFS(Data!$D$2:$D$151,Data!$B$2:$B$151,B$14,Data!$A$2:$A$151,$A23) -> 66 | C23: =SUMIFS(Data!$D$2:$D$151,Data!$B$2:$B$151,C$14,Data!$A$2:$A$151,$A23) -> 79 | D23: =SUMIFS(Data!$D$2:$D$151,Data!$B$2:$B$151,D$14,Data!$A$2:$A$151,$A23) -> 65 | E23: =SUMIFS(Data!$D$2:$D$151,Data!$B$2:$B$151,E$14,Data!$A$2:$A$151,$A23) -> 32 | F23: =SUMIFS(Data!$D$2:$D$151,Data!$B$2:$B$151,F$14,Data!$A$2:$A$151,$A23) -> 34 | G23: =SUM(B23:F23) -> 276 | H23: =AVERAGE(G16:G22) -> 284.71429 | J23: =AVERAGE(B16:B22) -> 59 | K23: =AVERAGE(C16:C22) -> 66.857143 | L23: =AVERAGE(D16:D22) -> 86.714286 | M23: =AVERAGE(E16:E22) -> 42 | N23: =AVERAGE(F16:F22) -> 30.142857
A24: =A23+1 -> 46275 | B24: =SUMIFS(Data!$D$2:$D$151,Data!$B$2:$B$151,B$14,Data!$A$2:$A$151,$A24) -> 57 | C24: =SUMIFS(Data!$D$2:$D$151,Data!$B$2:$B$151,C$14,Data!$A$2:$A$151,$A24) -> 69 | D24: =SUMIFS(Data!$D$2:$D$151,Data!$B$2:$B$151,D$14,Data!$A$2:$A$151,$A24) -> 81 | E24: =SUMIFS(Data!$D$2:$D$151,Data!$B$2:$B$151,E$14,Data!$A$2:$A$151,$A24) -> 30 | F24: =SUMIFS(Data!$D$2:$D$151,Data!$B$2:$B$151,F$14,Data!$A$2:$A$151,$A24) -> 34 | G24: =SUM(B24:F24) -> 271 | H24: =AVERAGE(G17:G23) -> 285.42857 | J24: =AVERAGE(B17:B23) -> 60 | K24: =AVERAGE(C17:C23) -> 67.714286 | L24: =AVERAGE(D17:D23) -> 84.571429 | M24: =AVERAGE(E17:E23) -> 41.857143 | N24: =AVERAGE(F17:F23) -> 31.285714
A25: =A24+1 -> 46276 | B25: =SUMIFS(Data!$D$2:$D$151,Data!$B$2:$B$151,B$14,Data!$A$2:$A$151,$A25) -> 62 | C25: =SUMIFS(Data!$D$2:$D$151,Data!$B$2:$B$151,C$14,Data!$A$2:$A$151,$A25) -> 75 | D25: =SUMIFS(Data!$D$2:$D$151,Data!$B$2:$B$151,D$14,Data!$A$2:$A$151,$A25) -> 74 | E25: =SUMIFS(Data!$D$2:$D$151,Data!$B$2:$B$151,E$14,Data!$A$2:$A$151,$A25) -> 46 | F25: =SUMIFS(Data!$D$2:$D$151,Data!$B$2:$B$151,F$14,Data!$A$2:$A$151,$A25) -> 36 | G25: =SUM(B25:F25) -> 293 | H25: =AVERAGE(G18:G24) -> 280.71429 | J25: =AVERAGE(B18:B24) -> 58.714286 | K25: =AVERAGE(C18:C24) -> 68.142857 | L25: =AVERAGE(D18:D24) -> 83.285714 | M25: =AVERAGE(E18:E24) -> 39.714286 | N25: =AVERAGE(F18:F24) -> 30.857143
A26: =A25+1 -> 46277 | B26: =SUMIFS(Data!$D$2:$D$151,Data!$B$2:$B$151,B$14,Data!$A$2:$A$151,$A26) -> 61 | C26: =SUMIFS(Data!$D$2:$D$151,Data!$B$2:$B$151,C$14,Data!$A$2:$A$151,$A26) -> 56 | D26: =SUMIFS(Data!$D$2:$D$151,Data!$B$2:$B$151,D$14,Data!$A$2:$A$151,$A26) -> 65 | E26: =SUMIFS(Data!$D$2:$D$151,Data!$B$2:$B$151,E$14,Data!$A$2:$A$151,$A26) -> 31 | F26: =SUMIFS(Data!$D$2:$D$151,Data!$B$2:$B$151,F$14,Data!$A$2:$A$151,$A26) -> 23 | G26: =SUM(B26:F26) -> 236 | H26: =AVERAGE(G19:G25) -> 282.28571 | J26: =AVERAGE(B19:B25) -> 56.857143 | K26: =AVERAGE(C19:C25) -> 70 | L26: =AVERAGE(D19:D25) -> 84 | M26: =AVERAGE(E19:E25) -> 40 | N26: =AVERAGE(F19:F25) -> 31.428571
A27: =A26+1 -> 46278 | B27: =SUMIFS(Data!$D$2:$D$151,Data!$B$2:$B$151,B$14,Data!$A$2:$A$151,$A27) -> 64 | C27: =SUMIFS(Data!$D$2:$D$151,Data!$B$2:$B$151,C$14,Data!$A$2:$A$151,$A27) -> 75 | D27: =SUMIFS(Data!$D$2:$D$151,Data!$B$2:$B$151,D$14,Data!$A$2:$A$151,$A27) -> 67 | E27: =SUMIFS(Data!$D$2:$D$151,Data!$B$2:$B$151,E$14,Data!$A$2:$A$151,$A27) -> 48 | F27: =SUMIFS(Data!$D$2:$D$151,Data!$B$2:$B$151,F$14,Data!$A$2:$A$151,$A27) -> 33 | G27: =SUM(B27:F27) -> 287 | H27: =AVERAGE(G20:G26) -> 273 | J27: =AVERAGE(B20:B26) -> 58.571429 | K27: =AVERAGE(C20:C26) -> 66.428571 | L27: =AVERAGE(D20:D26) -> 79 | M27: =AVERAGE(E20:E26) -> 37.857143 | N27: =AVERAGE(F20:F26) -> 31.142857
A28: =A27+1 -> 46279 | B28: =SUMIFS(Data!$D$2:$D$151,Data!$B$2:$B$151,B$14,Data!$A$2:$A$151,$A28) -> 69 | C28: =SUMIFS(Data!$D$2:$D$151,Data!$B$2:$B$151,C$14,Data!$A$2:$A$151,$A28) -> 87 | D28: =SUMIFS(Data!$D$2:$D$151,Data!$B$2:$B$151,D$14,Data!$A$2:$A$151,$A28) -> 90 | E28: =SUMIFS(Data!$D$2:$D$151,Data!$B$2:$B$151,E$14,Data!$A$2:$A$151,$A28) -> 39 | F28: =SUMIFS(Data!$D$2:$D$151,Data!$B$2:$B$151,F$14,Data!$A$2:$A$151,$A28) -> 39 | G28: =SUM(B28:F28) -> 324 | H28: =AVERAGE(G21:G27) -> 274.71429 | J28: =AVERAGE(B21:B27) -> 60.285714 | K28: =AVERAGE(C21:C27) -> 69.714286 | L28: =AVERAGE(D21:D27) -> 73.714286 | M28: =AVERAGE(E21:E27) -> 40.142857 | N28: =AVERAGE(F21:F27) -> 30.857143
A29: =A28+1 -> 46280 | B29: =SUMIFS(Data!$D$2:$D$151,Data!$B$2:$B$151,B$14,Data!$A$2:$A$151,$A29) -> 46 | C29: =SUMIFS(Data!$D$2:$D$151,Data!$B$2:$B$151,C$14,Data!$A$2:$A$151,$A29) -> 82 | D29: =SUMIFS(Data!$D$2:$D$151,Data!$B$2:$B$151,D$14,Data!$A$2:$A$151,$A29) -> 100 | E29: =SUMIFS(Data!$D$2:$D$151,Data!$B$2:$B$151,E$14,Data!$A$2:$A$151,$A29) -> 38 | F29: =SUMIFS(Data!$D$2:$D$151,Data!$B$2:$B$151,F$14,Data!$A$2:$A$151,$A29) -> 36 | G29: =SUM(B29:F29) -> 302 | H29: =AVERAGE(G22:G28) -> 278.42857 | J29: =AVERAGE(B22:B28) -> 61.571429 | K29: =AVERAGE(C22:C28) -> 71.142857 | L29: =AVERAGE(D22:D28) -> 74.714286 | M29: =AVERAGE(E22:E28) -> 39.142857 | N29: =AVERAGE(F22:F28) -> 31.857143
A30: =A29+1 -> 46281 | B30: =SUMIFS(Data!$D$2:$D$151,Data!$B$2:$B$151,B$14,Data!$A$2:$A$151,$A30) -> 48 | C30: =SUMIFS(Data!$D$2:$D$151,Data!$B$2:$B$151,C$14,Data!$A$2:$A$151,$A30) -> 70 | D30: =SUMIFS(Data!$D$2:$D$151,Data!$B$2:$B$151,D$14,Data!$A$2:$A$151,$A30) -> 71 | E30: =SUMIFS(Data!$D$2:$D$151,Data!$B$2:$B$151,E$14,Data!$A$2:$A$151,$A30) -> 36 | F30: =SUMIFS(Data!$D$2:$D$151,Data!$B$2:$B$151,F$14,Data!$A$2:$A$151,$A30) -> 34 | G30: =SUM(B30:F30) -> 259 | H30: =AVERAGE(G23:G29) -> 284.14286 | J30: =AVERAGE(B23:B29) -> 60.714286 | K30: =AVERAGE(C23:C29) -> 74.714286 | L30: =AVERAGE(D23:D29) -> 77.428571 | M30: =AVERAGE(E23:E29) -> 37.714286 | N30: =AVERAGE(F23:F29) -> 33.571429
A31: =A30+1 -> 46282 | B31: =SUMIFS(Data!$D$2:$D$151,Data!$B$2:$B$151,B$14,Data!$A$2:$A$151,$A31) -> 47 | C31: =SUMIFS(Data!$D$2:$D$151,Data!$B$2:$B$151,C$14,Data!$A$2:$A$151,$A31) -> 66 | D31: =SUMIFS(Data!$D$2:$D$151,Data!$B$2:$B$151,D$14,Data!$A$2:$A$151,$A31) -> 98 | E31: =SUMIFS(Data!$D$2:$D$151,Data!$B$2:$B$151,E$14,Data!$A$2:$A$151,$A31) -> 34 | F31: =SUMIFS(Data!$D$2:$D$151,Data!$B$2:$B$151,F$14,Data!$A$2:$A$151,$A31) -> 24 | G31: =SUM(B31:F31) -> 269 | H31: =AVERAGE(G24:G30) -> 281.71429 | J31: =AVERAGE(B24:B30) -> 58.142857 | K31: =AVERAGE(C24:C30) -> 73.428571 | L31: =AVERAGE(D24:D30) -> 78.285714 | M31: =AVERAGE(E24:E30) -> 38.285714 | N31: =AVERAGE(F24:F30) -> 33.571429
A32: =A31+1 -> 46283 | B32: =SUMIFS(Data!$D$2:$D$151,Data!$B$2:$B$151,B$14,Data!$A$2:$A$151,$A32) -> 76 | C32: =SUMIFS(Data!$D$2:$D$151,Data!$B$2:$B$151,C$14,Data!$A$2:$A$151,$A32) -> 75 | D32: =SUMIFS(Data!$D$2:$D$151,Data!$B$2:$B$151,D$14,Data!$A$2:$A$151,$A32) -> 58 | E32: =SUMIFS(Data!$D$2:$D$151,Data!$B$2:$B$151,E$14,Data!$A$2:$A$151,$A32) -> 40 | F32: =SUMIFS(Data!$D$2:$D$151,Data!$B$2:$B$151,F$14,Data!$A$2:$A$151,$A32) -> 24 | G32: =SUM(B32:F32) -> 273 | H32: =AVERAGE(G25:G31) -> 281.42857 | J32: =AVERAGE(B25:B31) -> 56.714286 | K32: =AVERAGE(C25:C31) -> 73 | L32: =AVERAGE(D25:D31) -> 80.714286 | M32: =AVERAGE(E25:E31) -> 38.857143 | N32: =AVERAGE(F25:F31) -> 32.142857
A33: =A32+1 -> 46284 | B33: =SUMIFS(Data!$D$2:$D$151,Data!$B$2:$B$151,B$14,Data!$A$2:$A$151,$A33) -> 47 | C33: =SUMIFS(Data!$D$2:$D$151,Data!$B$2:$B$151,C$14,Data!$A$2:$A$151,$A33) -> 84 | D33: =SUMIFS(Data!$D$2:$D$151,Data!$B$2:$B$151,D$14,Data!$A$2:$A$151,$A33) -> 89 | E33: =SUMIFS(Data!$D$2:$D$151,Data!$B$2:$B$151,E$14,Data!$A$2:$A$151,$A33) -> 37 | F33: =SUMIFS(Data!$D$2:$D$151,Data!$B$2:$B$151,F$14,Data!$A$2:$A$151,$A33) -> 31 | G33: =SUM(B33:F33) -> 288 | H33: =AVERAGE(G26:G32) -> 278.57143 | J33: =AVERAGE(B26:B32) -> 58.714286 | K33: =AVERAGE(C26:C32) -> 73 | L33: =AVERAGE(D26:D32) -> 78.428571 | M33: =AVERAGE(E26:E32) -> 38 | N33: =AVERAGE(F26:F32) -> 30.428571
... A44: =A43+1 -> 46295 | B44: =SUMIFS(Data!$D$2:$D$151,Data!$B$2:$B$151,B$14,Data!$A$2:$A$151,$A44) -> 49 | C44: =SUMIFS(Data!$D$2:$D$151,Data!$B$2:$B$151,C$14,Data!$A$2:$A$151,$A44) -> 59 | D44: =SUMIFS(Data!$D$2:$D$151,Data!$B$2:$B$151,D$14,Data!$A$2:$A$151,$A44) -> 64 | E44: =SUMIFS(Data!$D$2:$D$151,Data!$B$2:$B$151,E$14,Data!$A$2:$A$151,$A44) -> 43 | F44: =SUMIFS(Data!$D$2:$D$151,Data!$B$2:$B$151,F$14,Data!$A$2:$A$151,$A44) -> 29 | G44: =SUM(B44:F44) -> 244 | H44: =AVERAGE(G37:G43) -> 293 | J44: =AVERAGE(B37:B43) -> 67.857143 | K44: =AVERAGE(C37:C43) -> 75.285714 | L44: =AVERAGE(D37:D43) -> 79.142857 | M44: =AVERAGE(E37:E43) -> 41.857143 | N44: =AVERAGE(F37:F43) -> 28.857143
A45: =A44+1 -> 46296 | H45: =AVERAGE($G$38:$G$44) -> 285.71429 | I45: Future days ▼ (grey) use the latest 7-day average
A46: =A45+1 -> 46297 | H46: =AVERAGE($G$38:$G$44) -> 285.71429
A47: =A46+1 -> 46298 | H47: =AVERAGE($G$38:$G$44) -> 285.71429
A48: =A47+1 -> 46299 | H48: =AVERAGE($G$38:$G$44) -> 285.71429
A49: =A48+1 -> 46300 | H49: =AVERAGE($G$38:$G$44) -> 285.71429
A50: =A49+1 -> 46301 | H50: =AVERAGE($G$38:$G$44) -> 285.71429
A51: =A50+1 -> 46302 | H51: =AVERAGE($G$38:$G$44) -> 285.71429
...

Sheet Inventory
A1: 2 · Inventory, Safety Stock & Reorder Point
A2: Safety stock = Z × demand std. dev. × √lead time. Reorder point = avg daily demand × lead time + safety stock. Yellow cells can be changed.
A3: Service level (target) | B3: 0.95 | C3: Chance of NOT running out of stock in a lead time (assumption)
A4: Order cycle (days) | B4: 4 | C4: How often we place an order for each product (assumption)
A5: Z-value | B5: =NORMSINV(B3) -> 1.6448536
A8: Product | B8: Avg daily demand (kg) | C8: Demand std. dev. (kg) | D8: Lead time (days) | E8: Safety stock – recommended (kg) | F8: Safety stock – current (kg) | G8: Reorder point – recommended (kg) | H8: Reorder point – current (kg) | I8: Stock now, 30-Sep (kg) | J8: Days of cover now | K8: Stock status | L8: Order in (days) | M8: Next order date | N8: Suggested order qty (kg) | O8: Avg stock held (kg) | P8: Target avg stock (kg) | Q8: Excess stock (kg) | R8: Stockout days | S8: Avg fill rate | T8: Days below reorder pt
A9: Tomato | B9: =AVERAGEIFS(Data!$D$2:$D$151,Data!$B$2:$B$151,$A9) -> 60.566667 | C9: =SQRT(SUMPRODUCT((Data!$B$2:$B$151=$A9)*(Data!$D$2:$D$151-B9)^2)/(COUNTIF(Data!$B$2:$B$151,$A9)-1)) -> 10.115483 | D9: =AVERAGEIFS(Data!$G$2:$G$151,Data!$B$2:$B$151,$A9) -> 3 | E9: =ROUND($B$5*C9*SQRT(D9),0) -> 29 | F9: =AVERAGEIFS(Data!$I$2:$I$151,Data!$B$2:$B$151,$A9) -> 51.866667 | G9: =ROUND(B9*D9+E9,0) -> 211 | H9: =AVERAGEIFS(Data!$J$2:$J$151,Data!$B$2:$B$151,$A9) -> 231.36667 | I9: =SUMIFS(Data!$F$2:$F$151,Data!$B$2:$B$151,$A9,Data!$A$2:$A$151,MAX(Data!$A$2:$A$151)) -> 349 | J9: =I9/B9 -> 5.7622455 | K9: =IF(I9<G9,"ORDER NOW",IF(I9<G9*1.2,"WATCH","OK")) -> OK | L9: =MAX(0,(I9-G9)/B9) -> 2.278481 | M9: =MAX(Data!$A$2:$A$151)+ROUNDDOWN(L9,0) -> 46297 | N9: =CEILING(B9*$B$4,10) -> 250 | O9: =AVERAGEIFS(Data!$F$2:$F$151,Data!$B$2:$B$151,$A9) -> 317.9 | P9: =E9+N9/2 -> 154 | Q9: =MAX(0,O9-P9) -> 163.9 | R9: =SUMIFS(Data!$P$2:$P$151,Data!$B$2:$B$151,$A9) -> 0 | S9: =AVERAGEIFS(Data!$L$2:$L$151,Data!$B$2:$B$151,$A9) -> 1 | T9: =SUMIFS(Data!$O$2:$O$151,Data!$B$2:$B$151,$A9) -> 7
A10: Onion | B10: =AVERAGEIFS(Data!$D$2:$D$151,Data!$B$2:$B$151,$A10) -> 72.8 | C10: =SQRT(SUMPRODUCT((Data!$B$2:$B$151=$A10)*(Data!$D$2:$D$151-B10)^2)/(COUNTIF(Data!$B$2:$B$151,$A10)-1)) -> 10.443279 | D10: =AVERAGEIFS(Data!$G$2:$G$151,Data!$B$2:$B$151,$A10) -> 4 | E10: =ROUND($B$5*C10*SQRT(D10),0) -> 34 | F10: =AVERAGEIFS(Data!$I$2:$I$151,Data!$B$2:$B$151,$A10) -> 73.133333 | G10: =ROUND(B10*D10+E10,0) -> 325 | H10: =AVERAGEIFS(Data!$J$2:$J$151,Data!$B$2:$B$151,$A10) -> 366 | I10: =SUMIFS(Data!$F$2:$F$151,Data!$B$2:$B$151,$A10,Data!$A$2:$A$151,MAX(Data!$A$2:$A$151)) -> 584 | J10: =I10/B10 -> 8.021978 | K10: =IF(I10<G10,"ORDER NOW",IF(I10<G10*1.2,"WATCH","OK")) -> OK | L10: =MAX(0,(I10-G10)/B10) -> 3.5576923 | M10: =MAX(Data!$A$2:$A$151)+ROUNDDOWN(L10,0) -> 46298 | N10: =CEILING(B10*$B$4,10) -> 300 | O10: =AVERAGEIFS(Data!$F$2:$F$151,Data!$B$2:$B$151,$A10) -> 500.83333 | P10: =E10+N10/2 -> 184 | Q10: =MAX(0,O10-P10) -> 316.83333 | R10: =SUMIFS(Data!$P$2:$P$151,Data!$B$2:$B$151,$A10) -> 0 | S10: =AVERAGEIFS(Data!$L$2:$L$151,Data!$B$2:$B$151,$A10) -> 1 | T10: =SUMIFS(Data!$O$2:$O$151,Data!$B$2:$B$151,$A10) -> 5
A11: Potato | B11: =AVERAGEIFS(Data!$D$2:$D$151,Data!$B$2:$B$151,$A11) -> 79.033333 | C11: =SQRT(SUMPRODUCT((Data!$B$2:$B$151=$A11)*(Data!$D$2:$D$151-B11)^2)/(COUNTIF(Data!$B$2:$B$151,$A11)-1)) -> 14.325004 | D11: =AVERAGEIFS(Data!$G$2:$G$151,Data!$B$2:$B$151,$A11) -> 4 | E11: =ROUND($B$5*C11*SQRT(D11),0) -> 47 | F11: =AVERAGEIFS(Data!$I$2:$I$151,Data!$B$2:$B$151,$A11) -> 79.466667 | G11: =ROUND(B11*D11+E11,0) -> 363 | H11: =AVERAGEIFS(Data!$J$2:$J$151,Data!$B$2:$B$151,$A11) -> 397.23333 | I11: =SUMIFS(Data!$F$2:$F$151,Data!$B$2:$B$151,$A11,Data!$A$2:$A$151,MAX(Data!$A$2:$A$151)) -> 745 | J11: =I11/B11 -> 9.4264024 | K11: =IF(I11<G11,"ORDER NOW",IF(I11<G11*1.2,"WATCH","OK")) -> OK | L11: =MAX(0,(I11-G11)/B11) -> 4.8334036 | M11: =MAX(Data!$A$2:$A$151)+ROUNDDOWN(L11,0) -> 46299 | N11: =CEILING(B11*$B$4,10) -> 320 | O11: =AVERAGEIFS(Data!$F$2:$F$151,Data!$B$2:$B$151,$A11) -> 550.16667 | P11: =E11+N11/2 -> 207 | Q11: =MAX(0,O11-P11) -> 343.16667 | R11: =SUMIFS(Data!$P$2:$P$151,Data!$B$2:$B$151,$A11) -> 0 | S11: =AVERAGEIFS(Data!$L$2:$L$151,Data!$B$2:$B$151,$A11) -> 1 | T11: =SUMIFS(Data!$O$2:$O$151,Data!$B$2:$B$151,$A11) -> 6
A12: Cucumber | B12: =AVERAGEIFS(Data!$D$2:$D$151,Data!$B$2:$B$151,$A12) -> 39.566667 | C12: =SQRT(SUMPRODUCT((Data!$B$2:$B$151=$A12)*(Data!$D$2:$D$151-B12)^2)/(COUNTIF(Data!$B$2:$B$151,$A12)-1)) -> 6.6988591 | D12: =AVERAGEIFS(Data!$G$2:$G$151,Data!$B$2:$B$151,$A12) -> 2 | E12: =ROUND($B$5*C12*SQRT(D12),0) -> 16 | F12: =AVERAGEIFS(Data!$I$2:$I$151,Data!$B$2:$B$151,$A12) -> 27.3 | G12: =ROUND(B12*D12+E12,0) -> 95 | H12: =AVERAGEIFS(Data!$J$2:$J$151,Data!$B$2:$B$151,$A12) -> 104.66667 | I12: =SUMIFS(Data!$F$2:$F$151,Data!$B$2:$B$151,$A12,Data!$A$2:$A$151,MAX(Data!$A$2:$A$151)) -> 129 | J12: =I12/B12 -> 3.2603201 | K12: =IF(I12<G12,"ORDER NOW",IF(I12<G12*1.2,"WATCH","OK")) -> OK | L12: =MAX(0,(I12-G12)/B12) -> 0.85930918 | M12: =MAX(Data!$A$2:$A$151)+ROUNDDOWN(L12,0) -> 46295 | N12: =CEILING(B12*$B$4,10) -> 160 | O12: =AVERAGEIFS(Data!$F$2:$F$151,Data!$B$2:$B$151,$A12) -> 140.1 | P12: =E12+N12/2 -> 96 | Q12: =MAX(0,O12-P12) -> 44.1 | R12: =SUMIFS(Data!$P$2:$P$151,Data!$B$2:$B$151,$A12) -> 0 | S12: =AVERAGEIFS(Data!$L$2:$L$151,Data!$B$2:$B$151,$A12) -> 1 | T12: =SUMIFS(Data!$O$2:$O$151,Data!$B$2:$B$151,$A12) -> 8
A13: Capsicum | B13: =AVERAGEIFS(Data!$D$2:$D$151,Data!$B$2:$B$151,$A13) -> 30.666667 | C13: =SQRT(SUMPRODUCT((Data!$B$2:$B$151=$A13)*(Data!$D$2:$D$151-B13)^2)/(COUNTIF(Data!$B$2:$B$151,$A13)-1)) -> 4.9711813 | D13: =AVERAGEIFS(Data!$G$2:$G$151,Data!$B$2:$B$151,$A13) -> 3 | E13: =ROUND($B$5*C13*SQRT(D13),0) -> 14 | F13: =AVERAGEIFS(Data!$I$2:$I$151,Data!$B$2:$B$151,$A13) -> 26.9 | G13: =ROUND(B13*D13+E13,0) -> 106 | H13: =AVERAGEIFS(Data!$J$2:$J$151,Data!$B$2:$B$151,$A13) -> 120.03333 | I13: =SUMIFS(Data!$F$2:$F$151,Data!$B$2:$B$151,$A13,Data!$A$2:$A$151,MAX(Data!$A$2:$A$151)) -> 87 | J13: =I13/B13 -> 2.8369565 | K13: =IF(I13<G13,"ORDER NOW",IF(I13<G13*1.2,"WATCH","OK")) -> ORDER NOW | L13: =MAX(0,(I13-G13)/B13) -> 0 | M13: =MAX(Data!$A$2:$A$151)+ROUNDDOWN(L13,0) -> 46295 | N13: =CEILING(B13*$B$4,10) -> 130 | O13: =AVERAGEIFS(Data!$F$2:$F$151,Data!$B$2:$B$151,$A13) -> 160.8 | P13: =E13+N13/2 -> 79 | Q13: =MAX(0,O13-P13) -> 81.8 | R13: =SUMIFS(Data!$P$2:$P$151,Data!$B$2:$B$151,$A13) -> 0 | S13: =AVERAGEIFS(Data!$L$2:$L$151,Data!$B$2:$B$151,$A13) -> 1 | T13: =SUMIFS(Data!$O$2:$O$151,Data!$B$2:$B$151,$A13) -> 6
A14: Total | B14: =SUM(B9:B13) -> 282.63333 | E14: =SUM(E9:E13) -> 140 | F14: =SUM(F9:F13) -> 258.66667 | G14: =SUM(G9:G13) -> 1100 | H14: =SUM(H9:H13) -> 1219.3 | I14: =SUM(I9:I13) -> 1894 | J14: =I14/B14 -> 6.7012619 | N14: =SUM(N9:N13) -> 1160 | O14: =SUM(O9:O13) -> 1669.8 | P14: =SUM(P9:P13) -> 720 | Q14: =SUM(Q9:Q13) -> 949.8 | R14: =SUM(R9:R13) -> 0 | S14: =AVERAGE(Data!$L$2:$L$151) -> 1 | T14: =SUM(T9:T13) -> 32
A15: Target avg stock = recommended safety stock + half an order (the average level if we order every cycle). Excess = average stock held above that target. Status: ORDER NOW = below reorder point; WATCH = within 20% above it.
A17: Stock tracker for the product selected on the Dashboard (feeds the chart)
A19: Date | B19: =Dashboard!$D$33&" closing stock" -> Tomato closing stock | C19: Stock received (kg) | D19: Reorder point (kg) | E19: Safety stock (kg) | F19: Demand (kg)
A20: =Demand!A15 -> 46266 | B20: =SUMIFS(Data!$F$2:$F$151,Data!$B$2:$B$151,Dashboard!$D$33,Data!$A$2:$A$151,$A20) -> 322 | C20: =SUMIFS(Data!$E$2:$E$151,Data!$B$2:$B$151,Dashboard!$D$33,Data!$A$2:$A$151,$A20) -> 0 | D20: =INDEX($G$9:$G$13,MATCH(Dashboard!$D$33,$A$9:$A$13,0)) -> 211 | E20: =INDEX($E$9:$E$13,MATCH(Dashboard!$D$33,$A$9:$A$13,0)) -> 29 | F20: =SUMIFS(Data!$D$2:$D$151,Data!$B$2:$B$151,Dashboard!$D$33,Data!$A$2:$A$151,$A20) -> 48
A21: =Demand!A16 -> 46267 | B21: =SUMIFS(Data!$F$2:$F$151,Data!$B$2:$B$151,Dashboard!$D$33,Data!$A$2:$A$151,$A21) -> 263 | C21: =SUMIFS(Data!$E$2:$E$151,Data!$B$2:$B$151,Dashboard!$D$33,Data!$A$2:$A$151,$A21) -> 0 | D21: =INDEX($G$9:$G$13,MATCH(Dashboard!$D$33,$A$9:$A$13,0)) -> 211 | E21: =INDEX($E$9:$E$13,MATCH(Dashboard!$D$33,$A$9:$A$13,0)) -> 29 | F21: =SUMIFS(Data!$D$2:$D$151,Data!$B$2:$B$151,Dashboard!$D$33,Data!$A$2:$A$151,$A21) -> 59
A22: =Demand!A17 -> 46268 | B22: =SUMIFS(Data!$F$2:$F$151,Data!$B$2:$B$151,Dashboard!$D$33,Data!$A$2:$A$151,$A22) -> 197 | C22: =SUMIFS(Data!$E$2:$E$151,Data!$B$2:$B$151,Dashboard!$D$33,Data!$A$2:$A$151,$A22) -> 0 | D22: =INDEX($G$9:$G$13,MATCH(Dashboard!$D$33,$A$9:$A$13,0)) -> 211 | E22: =INDEX($E$9:$E$13,MATCH(Dashboard!$D$33,$A$9:$A$13,0)) -> 29 | F22: =SUMIFS(Data!$D$2:$D$151,Data!$B$2:$B$151,Dashboard!$D$33,Data!$A$2:$A$151,$A22) -> 66
A23: =Demand!A18 -> 46269 | B23: =SUMIFS(Data!$F$2:$F$151,Data!$B$2:$B$151,Dashboard!$D$33,Data!$A$2:$A$151,$A23) -> 410 | C23: =SUMIFS(Data!$E$2:$E$151,Data!$B$2:$B$151,Dashboard!$D$33,Data!$A$2:$A$151,$A23) -> 288 | D23: =INDEX($G$9:$G$13,MATCH(Dashboard!$D$33,$A$9:$A$13,0)) -> 211 | E23: =INDEX($E$9:$E$13,MATCH(Dashboard!$D$33,$A$9:$A$13,0)) -> 29 | F23: =SUMIFS(Data!$D$2:$D$151,Data!$B$2:$B$151,Dashboard!$D$33,Data!$A$2:$A$151,$A23) -> 75
A24: =Demand!A19 -> 46270 | B24: =SUMIFS(Data!$F$2:$F$151,Data!$B$2:$B$151,Dashboard!$D$33,Data!$A$2:$A$151,$A24) -> 361 | C24: =SUMIFS(Data!$E$2:$E$151,Data!$B$2:$B$151,Dashboard!$D$33,Data!$A$2:$A$151,$A24) -> 0 | D24: =INDEX($G$9:$G$13,MATCH(Dashboard!$D$33,$A$9:$A$13,0)) -> 211 | E24: =INDEX($E$9:$E$13,MATCH(Dashboard!$D$33,$A$9:$A$13,0)) -> 29 | F24: =SUMIFS(Data!$D$2:$D$151,Data!$B$2:$B$151,Dashboard!$D$33,Data!$A$2:$A$151,$A24) -> 49
A25: =Demand!A20 -> 46271 | B25: =SUMIFS(Data!$F$2:$F$151,Data!$B$2:$B$151,Dashboard!$D$33,Data!$A$2:$A$151,$A25) -> 247 | C25: =SUMIFS(Data!$E$2:$E$151,Data!$B$2:$B$151,Dashboard!$D$33,Data!$A$2:$A$151,$A25) -> 0 | D25: =INDEX($G$9:$G$13,MATCH(Dashboard!$D$33,$A$9:$A$13,0)) -> 211 | E25: =INDEX($E$9:$E$13,MATCH(Dashboard!$D$33,$A$9:$A$13,0)) -> 29 | F25: =SUMIFS(Data!$D$2:$D$151,Data!$B$2:$B$151,Dashboard!$D$33,Data!$A$2:$A$151,$A25) -> 52
A26: =Demand!A21 -> 46272 | B26: =SUMIFS(Data!$F$2:$F$151,Data!$B$2:$B$151,Dashboard!$D$33,Data!$A$2:$A$151,$A26) -> 187 | C26: =SUMIFS(Data!$E$2:$E$151,Data!$B$2:$B$151,Dashboard!$D$33,Data!$A$2:$A$151,$A26) -> 0 | D26: =INDEX($G$9:$G$13,MATCH(Dashboard!$D$33,$A$9:$A$13,0)) -> 211 | E26: =INDEX($E$9:$E$13,MATCH(Dashboard!$D$33,$A$9:$A$13,0)) -> 29 | F26: =SUMIFS(Data!$D$2:$D$151,Data!$B$2:$B$151,Dashboard!$D$33,Data!$A$2:$A$151,$A26) -> 60
A27: =Demand!A22 -> 46273 | B27: =SUMIFS(Data!$F$2:$F$151,Data!$B$2:$B$151,Dashboard!$D$33,Data!$A$2:$A$151,$A27) -> 427 | C27: =SUMIFS(Data!$E$2:$E$151,Data!$B$2:$B$151,Dashboard!$D$33,Data!$A$2:$A$151,$A27) -> 292 | D27: =INDEX($G$9:$G$13,MATCH(Dashboard!$D$33,$A$9:$A$13,0)) -> 211 | E27: =INDEX($E$9:$E$13,MATCH(Dashboard!$D$33,$A$9:$A$13,0)) -> 29 | F27: =SUMIFS(Data!$D$2:$D$151,Data!$B$2:$B$151,Dashboard!$D$33,Data!$A$2:$A$151,$A27) -> 52
A28: =Demand!A23 -> 46274 | B28: =SUMIFS(Data!$F$2:$F$151,Data!$B$2:$B$151,Dashboard!$D$33,Data!$A$2:$A$151,$A28) -> 361 | C28: =SUMIFS(Data!$E$2:$E$151,Data!$B$2:$B$151,Dashboard!$D$33,Data!$A$2:$A$151,$A28) -> 0 | D28: =INDEX($G$9:$G$13,MATCH(Dashboard!$D$33,$A$9:$A$13,0)) -> 211 | E28: =INDEX($E$9:$E$13,MATCH(Dashboard!$D$33,$A$9:$A$13,0)) -> 29 | F28: =SUMIFS(Data!$D$2:$D$151,Data!$B$2:$B$151,Dashboard!$D$33,Data!$A$2:$A$151,$A28) -> 66
A29: =Demand!A24 -> 46275 | B29: =SUMIFS(Data!$F$2:$F$151,Data!$B$2:$B$151,Dashboard!$D$33,Data!$A$2:$A$151,$A29) -> 304 | C29: =SUMIFS(Data!$E$2:$E$151,Data!$B$2:$B$151,Dashboard!$D$33,Data!$A$2:$A$151,$A29) -> 0 | D29: =INDEX($G$9:$G$13,MATCH(Dashboard!$D$33,$A$9:$A$13,0)) -> 211 | E29: =INDEX($E$9:$E$13,MATCH(Dashboard!$D$33,$A$9:$A$13,0)) -> 29 | F29: =SUMIFS(Data!$D$2:$D$151,Data!$B$2:$B$151,Dashboard!$D$33,Data!$A$2:$A$151,$A29) -> 57
A30: =Demand!A25 -> 46276 | B30: =SUMIFS(Data!$F$2:$F$151,Data!$B$2:$B$151,Dashboard!$D$33,Data!$A$2:$A$151,$A30) -> 194 | C30: =SUMIFS(Data!$E$2:$E$151,Data!$B$2:$B$151,Dashboard!$D$33,Data!$A$2:$A$151,$A30) -> 0 | D30: =INDEX($G$9:$G$13,MATCH(Dashboard!$D$33,$A$9:$A$13,0)) -> 211 | E30: =INDEX($E$9:$E$13,MATCH(Dashboard!$D$33,$A$9:$A$13,0)) -> 29 | F30: =SUMIFS(Data!$D$2:$D$151,Data!$B$2:$B$151,Dashboard!$D$33,Data!$A$2:$A$151,$A30) -> 62
A31: =Demand!A26 -> 46277 | B31: =SUMIFS(Data!$F$2:$F$151,Data!$B$2:$B$151,Dashboard!$D$33,Data!$A$2:$A$151,$A31) -> 417 | C31: =SUMIFS(Data!$E$2:$E$151,Data!$B$2:$B$151,Dashboard!$D$33,Data!$A$2:$A$151,$A31) -> 284 | D31: =INDEX($G$9:$G$13,MATCH(Dashboard!$D$33,$A$9:$A$13,0)) -> 211 | E31: =INDEX($E$9:$E$13,MATCH(Dashboard!$D$33,$A$9:$A$13,0)) -> 29 | F31: =SUMIFS(Data!$D$2:$D$151,Data!$B$2:$B$151,Dashboard!$D$33,Data!$A$2:$A$151,$A31) -> 61
... A49: =Demand!A44 -> 46295 | B49: =SUMIFS(Data!$F$2:$F$151,Data!$B$2:$B$151,Dashboard!$D$33,Data!$A$2:$A$151,$A49) -> 349 | C49: =SUMIFS(Data!$E$2:$E$151,Data!$B$2:$B$151,Dashboard!$D$33,Data!$A$2:$A$151,$A49) -> 0 | D49: =INDEX($G$9:$G$13,MATCH(Dashboard!$D$33,$A$9:$A$13,0)) -> 211 | E49: =INDEX($E$9:$E$13,MATCH(Dashboard!$D$33,$A$9:$A$13,0)) -> 29 | F49: =SUMIFS(Data!$D$2:$D$151,Data!$B$2:$B$151,Dashboard!$D$33,Data!$A$2:$A$151,$A49) -> 49

Sheet Waste
A1: 3 · Wastage & Expiry Analysis
A2: Waste = expired / damaged stock written off (kg). Prices below are ASSUMPTIONS for illustration – replace with real buying rates. Yellow cells can be changed.
A3: Waste reduction target | B3: 0.5 | C3: How much of the waste we aim to remove (assumption)
A8: Product | B8: Demand (kg) | C8: Waste (kg) | D8: Waste % of demand | E8: Waste events (days) | F8: Avg waste per event (kg) | G8: Share of total waste | H8: Assumed price (₹/kg) | I8: Est. waste value (₹) | J8: Waste saved at target (kg) | K8: Value saved at target (₹)
A9: Tomato | B9: =SUMIFS(Data!$D$2:$D$151,Data!$B$2:$B$151,$A9) -> 1817 | C9: =SUMIFS(Data!$K$2:$K$151,Data!$B$2:$B$151,$A9) -> 374 | D9: =C9/B9 -> 0.20583379 | E9: =COUNTIFS(Data!$B$2:$B$151,$A9,Data!$K$2:$K$151,">0") -> 6 | F9: =IF(E9>0,C9/E9,0) -> 62.333333 | G9: =C9/$C$14 -> 0.21310541 | H9: 25 | I9: =C9*H9 -> 9350 | J9: =C9*$B$3 -> 187 | K9: =J9*H9 -> 4675
A10: Onion | B10: =SUMIFS(Data!$D$2:$D$151,Data!$B$2:$B$151,$A10) -> 2184 | C10: =SUMIFS(Data!$K$2:$K$151,Data!$B$2:$B$151,$A10) -> 485 | D10: =C10/B10 -> 0.2220696 | E10: =COUNTIFS(Data!$B$2:$B$151,$A10,Data!$K$2:$K$151,">0") -> 6 | F10: =IF(E10>0,C10/E10,0) -> 80.833333 | G10: =C10/$C$14 -> 0.27635328 | H10: 30 | I10: =C10*H10 -> 14550 | J10: =C10*$B$3 -> 242.5 | K10: =J10*H10 -> 7275
A11: Potato | B11: =SUMIFS(Data!$D$2:$D$151,Data!$B$2:$B$151,$A11) -> 2371 | C11: =SUMIFS(Data!$K$2:$K$151,Data!$B$2:$B$151,$A11) -> 461 | D11: =C11/B11 -> 0.19443273 | E11: =COUNTIFS(Data!$B$2:$B$151,$A11,Data!$K$2:$K$151,">0") -> 6 | F11: =IF(E11>0,C11/E11,0) -> 76.833333 | G11: =C11/$C$14 -> 0.26267806 | H11: 22 | I11: =C11*H11 -> 10142 | J11: =C11*$B$3 -> 230.5 | K11: =J11*H11 -> 5071
A12: Cucumber | B12: =SUMIFS(Data!$D$2:$D$151,Data!$B$2:$B$151,$A12) -> 1187 | C12: =SUMIFS(Data!$K$2:$K$151,Data!$B$2:$B$151,$A12) -> 239 | D12: =C12/B12 -> 0.20134794 | E12: =COUNTIFS(Data!$B$2:$B$151,$A12,Data!$K$2:$K$151,">0") -> 6 | F12: =IF(E12>0,C12/E12,0) -> 39.833333 | G12: =C12/$C$14 -> 0.13618234 | H12: 28 | I12: =C12*H12 -> 6692 | J12: =C12*$B$3 -> 119.5 | K12: =J12*H12 -> 3346
A13: Capsicum | B13: =SUMIFS(Data!$D$2:$D$151,Data!$B$2:$B$151,$A13) -> 920 | C13: =SUMIFS(Data!$K$2:$K$151,Data!$B$2:$B$151,$A13) -> 196 | D13: =C13/B13 -> 0.21304348 | E13: =COUNTIFS(Data!$B$2:$B$151,$A13,Data!$K$2:$K$151,">0") -> 6 | F13: =IF(E13>0,C13/E13,0) -> 32.666667 | G13: =C13/$C$14 -> 0.11168091 | H13: 45 | I13: =C13*H13 -> 8820 | J13: =C13*$B$3 -> 98 | K13: =J13*H13 -> 4410
A14: Total | B14: =SUM(B9:B13) -> 8479 | C14: =SUM(C9:C13) -> 1755 | D14: =C14/B14 -> 0.20698196 | E14: =SUM(E9:E13) -> 30 | F14: =C14/E14 -> 58.5 | G14: =SUM(G9:G13) -> 1 | I14: =SUM(I9:I13) -> 49554 | J14: =SUM(J9:J13) -> 877.5 | K14: =SUM(K9:K13) -> 24777
A16: Days with waste | B16: =COUNTIF(G20:G49,">0") -> 6
A17: Biggest waste day (kg) | B17: =MAX(G20:G49) -> 352
A18: Daily waste (kg) by product
A19: Date | B19: Tomato | C19: Onion | D19: Potato | E19: Cucumber | F19: Capsicum | G19: Total waste (kg)
A20: =Demand!A15 -> 46266 | B20: =SUMIFS(Data!$K$2:$K$151,Data!$B$2:$B$151,B$19,Data!$A$2:$A$151,$A20) -> 80 | C20: =SUMIFS(Data!$K$2:$K$151,Data!$B$2:$B$151,C$19,Data!$A$2:$A$151,$A20) -> 86 | D20: =SUMIFS(Data!$K$2:$K$151,Data!$B$2:$B$151,D$19,Data!$A$2:$A$151,$A20) -> 75 | E20: =SUMIFS(Data!$K$2:$K$151,Data!$B$2:$B$151,E$19,Data!$A$2:$A$151,$A20) -> 67 | F20: =SUMIFS(Data!$K$2:$K$151,Data!$B$2:$B$151,F$19,Data!$A$2:$A$151,$A20) -> 44 | G20: =SUM(B20:F20) -> 352
A21: =Demand!A16 -> 46267 | B21: =SUMIFS(Data!$K$2:$K$151,Data!$B$2:$B$151,B$19,Data!$A$2:$A$151,$A21) -> 0 | C21: =SUMIFS(Data!$K$2:$K$151,Data!$B$2:$B$151,C$19,Data!$A$2:$A$151,$A21) -> 0 | D21: =SUMIFS(Data!$K$2:$K$151,Data!$B$2:$B$151,D$19,Data!$A$2:$A$151,$A21) -> 0 | E21: =SUMIFS(Data!$K$2:$K$151,Data!$B$2:$B$151,E$19,Data!$A$2:$A$151,$A21) -> 0 | F21: =SUMIFS(Data!$K$2:$K$151,Data!$B$2:$B$151,F$19,Data!$A$2:$A$151,$A21) -> 0 | G21: =SUM(B21:F21) -> 0
A22: =Demand!A17 -> 46268 | B22: =SUMIFS(Data!$K$2:$K$151,Data!$B$2:$B$151,B$19,Data!$A$2:$A$151,$A22) -> 0 | C22: =SUMIFS(Data!$K$2:$K$151,Data!$B$2:$B$151,C$19,Data!$A$2:$A$151,$A22) -> 0 | D22: =SUMIFS(Data!$K$2:$K$151,Data!$B$2:$B$151,D$19,Data!$A$2:$A$151,$A22) -> 0 | E22: =SUMIFS(Data!$K$2:$K$151,Data!$B$2:$B$151,E$19,Data!$A$2:$A$151,$A22) -> 0 | F22: =SUMIFS(Data!$K$2:$K$151,Data!$B$2:$B$151,F$19,Data!$A$2:$A$151,$A22) -> 0 | G22: =SUM(B22:F22) -> 0
A23: =Demand!A18 -> 46269 | B23: =SUMIFS(Data!$K$2:$K$151,Data!$B$2:$B$151,B$19,Data!$A$2:$A$151,$A23) -> 0 | C23: =SUMIFS(Data!$K$2:$K$151,Data!$B$2:$B$151,C$19,Data!$A$2:$A$151,$A23) -> 0 | D23: =SUMIFS(Data!$K$2:$K$151,Data!$B$2:$B$151,D$19,Data!$A$2:$A$151,$A23) -> 0 | E23: =SUMIFS(Data!$K$2:$K$151,Data!$B$2:$B$151,E$19,Data!$A$2:$A$151,$A23) -> 0 | F23: =SUMIFS(Data!$K$2:$K$151,Data!$B$2:$B$151,F$19,Data!$A$2:$A$151,$A23) -> 0 | G23: =SUM(B23:F23) -> 0
A24: =Demand!A19 -> 46270 | B24: =SUMIFS(Data!$K$2:$K$151,Data!$B$2:$B$151,B$19,Data!$A$2:$A$151,$A24) -> 0 | C24: =SUMIFS(Data!$K$2:$K$151,Data!$B$2:$B$151,C$19,Data!$A$2:$A$151,$A24) -> 0 | D24: =SUMIFS(Data!$K$2:$K$151,Data!$B$2:$B$151,D$19,Data!$A$2:$A$151,$A24) -> 0 | E24: =SUMIFS(Data!$K$2:$K$151,Data!$B$2:$B$151,E$19,Data!$A$2:$A$151,$A24) -> 0 | F24: =SUMIFS(Data!$K$2:$K$151,Data!$B$2:$B$151,F$19,Data!$A$2:$A$151,$A24) -> 0 | G24: =SUM(B24:F24) -> 0
A25: =Demand!A20 -> 46271 | B25: =SUMIFS(Data!$K$2:$K$151,Data!$B$2:$B$151,B$19,Data!$A$2:$A$151,$A25) -> 62 | C25: =SUMIFS(Data!$K$2:$K$151,Data!$B$2:$B$151,C$19,Data!$A$2:$A$151,$A25) -> 88 | D25: =SUMIFS(Data!$K$2:$K$151,Data!$B$2:$B$151,D$19,Data!$A$2:$A$151,$A25) -> 72 | E25: =SUMIFS(Data!$K$2:$K$151,Data!$B$2:$B$151,E$19,Data!$A$2:$A$151,$A25) -> 39 | F25: =SUMIFS(Data!$K$2:$K$151,Data!$B$2:$B$151,F$19,Data!$A$2:$A$151,$A25) -> 35 | G25: =SUM(B25:F25) -> 296
A26: =Demand!A21 -> 46272 | B26: =SUMIFS(Data!$K$2:$K$151,Data!$B$2:$B$151,B$19,Data!$A$2:$A$151,$A26) -> 0 | C26: =SUMIFS(Data!$K$2:$K$151,Data!$B$2:$B$151,C$19,Data!$A$2:$A$151,$A26) -> 0 | D26: =SUMIFS(Data!$K$2:$K$151,Data!$B$2:$B$151,D$19,Data!$A$2:$A$151,$A26) -> 0 | E26: =SUMIFS(Data!$K$2:$K$151,Data!$B$2:$B$151,E$19,Data!$A$2:$A$151,$A26) -> 0 | F26: =SUMIFS(Data!$K$2:$K$151,Data!$B$2:$B$151,F$19,Data!$A$2:$A$151,$A26) -> 0 | G26: =SUM(B26:F26) -> 0
A27: =Demand!A22 -> 46273 | B27: =SUMIFS(Data!$K$2:$K$151,Data!$B$2:$B$151,B$19,Data!$A$2:$A$151,$A27) -> 0 | C27: =SUMIFS(Data!$K$2:$K$151,Data!$B$2:$B$151,C$19,Data!$A$2:$A$151,$A27) -> 0 | D27: =SUMIFS(Data!$K$2:$K$151,Data!$B$2:$B$151,D$19,Data!$A$2:$A$151,$A27) -> 0 | E27: =SUMIFS(Data!$K$2:$K$151,Data!$B$2:$B$151,E$19,Data!$A$2:$A$151,$A27) -> 0 | F27: =SUMIFS(Data!$K$2:$K$151,Data!$B$2:$B$151,F$19,Data!$A$2:$A$151,$A27) -> 0 | G27: =SUM(B27:F27) -> 0
A28: =Demand!A23 -> 46274 | B28: =SUMIFS(Data!$K$2:$K$151,Data!$B$2:$B$151,B$19,Data!$A$2:$A$151,$A28) -> 0 | C28: =SUMIFS(Data!$K$2:$K$151,Data!$B$2:$B$151,C$19,Data!$A$2:$A$151,$A28) -> 0 | D28: =SUMIFS(Data!$K$2:$K$151,Data!$B$2:$B$151,D$19,Data!$A$2:$A$151,$A28) -> 0 | E28: =SUMIFS(Data!$K$2:$K$151,Data!$B$2:$B$151,E$19,Data!$A$2:$A$151,$A28) -> 0 | F28: =SUMIFS(Data!$K$2:$K$151,Data!$B$2:$B$151,F$19,Data!$A$2:$A$151,$A28) -> 0 | G28: =SUM(B28:F28) -> 0
A29: =Demand!A24 -> 46275 | B29: =SUMIFS(Data!$K$2:$K$151,Data!$B$2:$B$151,B$19,Data!$A$2:$A$151,$A29) -> 0 | C29: =SUMIFS(Data!$K$2:$K$151,Data!$B$2:$B$151,C$19,Data!$A$2:$A$151,$A29) -> 0 | D29: =SUMIFS(Data!$K$2:$K$151,Data!$B$2:$B$151,D$19,Data!$A$2:$A$151,$A29) -> 0 | E29: =SUMIFS(Data!$K$2:$K$151,Data!$B$2:$B$151,E$19,Data!$A$2:$A$151,$A29) -> 0 | F29: =SUMIFS(Data!$K$2:$K$151,Data!$B$2:$B$151,F$19,Data!$A$2:$A$151,$A29) -> 0 | G29: =SUM(B29:F29) -> 0
A30: =Demand!A25 -> 46276 | B30: =SUMIFS(Data!$K$2:$K$151,Data!$B$2:$B$151,B$19,Data!$A$2:$A$151,$A30) -> 48 | C30: =SUMIFS(Data!$K$2:$K$151,Data!$B$2:$B$151,C$19,Data!$A$2:$A$151,$A30) -> 82 | D30: =SUMIFS(Data!$K$2:$K$151,Data!$B$2:$B$151,D$19,Data!$A$2:$A$151,$A30) -> 79 | E30: =SUMIFS(Data!$K$2:$K$151,Data!$B$2:$B$151,E$19,Data!$A$2:$A$151,$A30) -> 18 | F30: =SUMIFS(Data!$K$2:$K$151,Data!$B$2:$B$151,F$19,Data!$A$2:$A$151,$A30) -> 27 | G30: =SUM(B30:F30) -> 254
A31: =Demand!A26 -> 46277 | B31: =SUMIFS(Data!$K$2:$K$151,Data!$B$2:$B$151,B$19,Data!$A$2:$A$151,$A31) -> 0 | C31: =SUMIFS(Data!$K$2:$K$151,Data!$B$2:$B$151,C$19,Data!$A$2:$A$151,$A31) -> 0 | D31: =SUMIFS(Data!$K$2:$K$151,Data!$B$2:$B$151,D$19,Data!$A$2:$A$151,$A31) -> 0 | E31: =SUMIFS(Data!$K$2:$K$151,Data!$B$2:$B$151,E$19,Data!$A$2:$A$151,$A31) -> 0 | F31: =SUMIFS(Data!$K$2:$K$151,Data!$B$2:$B$151,F$19,Data!$A$2:$A$151,$A31) -> 0 | G31: =SUM(B31:F31) -> 0
... A49: =Demand!A44 -> 46295 | B49: =SUMIFS(Data!$K$2:$K$151,Data!$B$2:$B$151,B$19,Data!$A$2:$A$151,$A49) -> 0 | C49: =SUMIFS(Data!$K$2:$K$151,Data!$B$2:$B$151,C$19,Data!$A$2:$A$151,$A49) -> 0 | D49: =SUMIFS(Data!$K$2:$K$151,Data!$B$2:$B$151,D$19,Data!$A$2:$A$151,$A49) -> 0 | E49: =SUMIFS(Data!$K$2:$K$151,Data!$B$2:$B$151,E$19,Data!$A$2:$A$151,$A49) -> 0 | F49: =SUMIFS(Data!$K$2:$K$151,Data!$B$2:$B$151,F$19,Data!$A$2:$A$151,$A49) -> 0 | G49: =SUM(B49:F49) -> 0

Sheet Recommendations
A1: 4 · Business Recommendations
A2: Each finding below is calculated from the data (live formulas). Actions are simple steps the supply chain team can follow.
A4: # | B4: Question | C4: What the data shows | D4: What we should do | E4: Expected benefit
A5: 1 | B5: What to order? | C5: ="Potato and Onion are "&TEXT((Waste!B10+Waste!B11)/Waste!B14,"0%")&" of all demand. Total demand moves between "&TEXT(MIN(Demand!G15:G44),"0")&" and "&TEXT(MAX(Demand!G15:G44),"0")&" kg per day, so a fixed order size is risky." -> Potato and Onion are 54% of all demand. Total demand moves between 236 and 333 kg per day, so a fixed order size is risky. | D5: Give Potato and Onion first priority in buying and storage space. Base every order on the 7-day average forecast and refresh the forecast every week. | E5: Right quantity ordered; fewer emergency purchases.
A6: 2 | B6: What to order? | C6: ="The 7-day average forecast is off by about "&TEXT(Demand!H10,"0.0%")&" per day for total demand ("&TEXT(Demand!I10,"0.0%")&" accurate). Product-level accuracy ranges from "&TEXT(MIN(Demand!I5:I9),"0%")&" to "&TEXT(MAX(Demand!I5:I9),"0%")&"." -> The 7-day average forecast is off by about 7.4% per day for total demand (92.6% accurate). Product-level accuracy ranges from 81% to 86%. | D6: Order quantity = forecast demand for the order cycle. Use the Suggested order qty column on the Inventory sheet. Add weekday, festival and weather effects when more data is available. | E6: Simple, explainable forecast the team can trust and improve.
A7: 3 | B7: When to order? | C7: ="Current reorder points add up to "&TEXT(Inventory!H14,"#,##0")&" kg; the calculated ones add up to "&TEXT(Inventory!G14,"#,##0")&" kg (difference "&TEXT(Inventory!H14-Inventory!G14,"#,##0")&" kg). Product-days below the current reorder point this month: "&Inventory!T14&" (out of 150)." -> Current reorder points add up to 1,219 kg; the calculated ones add up to 1,100 kg (difference 119 kg). Product-days below the current reorder point this month: 32 (out of 150). | D7: Use reorder point = avg daily demand × lead time + safety stock (95% service level). Review it every month with the operations team, and longest lead time items (Onion, Potato – 4 days) first. | E7: Lower stock held without risking stockouts.
A8: 4 | B8: When to order? | C8: =(COUNTIF(Inventory!K9:K13,"ORDER NOW")+COUNTIF(Inventory!K9:K13,"WATCH"))&" product(s) are at or near the reorder point today. Stockout days this month: "&Inventory!R14&"." -> 1 product(s) are at or near the reorder point today. Stockout days this month: 0. | D8: Use the Stock status column as a daily buying alert: ORDER NOW = place the order today; WATCH = call the supplier and keep the order ready. | E8: A simple daily routine for the procurement team.
A9: 5 | B9: How to reduce waste? | C9: ="Waste is "&TEXT(Waste!D14,"0.0%")&" of demand ("&TEXT(Waste!C14,"#,##0")&" kg). It is recorded on only "&Waste!B16&" of 30 days, in lumps of up to "&TEXT(Waste!B17,"0")&" kg – this looks like old stock being written off in batches." -> Waste is 20.7% of demand (1,755 kg). It is recorded on only 6 of 30 days, in lumps of up to 352 kg – this looks like old stock being written off in batches. | D9: Check stock age every day. Sell the oldest batch first (FEFO – First Expiry, First Out). Record received date and expiry date for every lot so the real cause (old stock, handling or quality) can be found. | E9: Find and remove the root cause of waste.
A10: 6 | B10: How to reduce waste? | C10: ="Average stock held is "&TEXT(Inventory!O14,"#,##0")&" kg against a target of "&TEXT(Inventory!P14,"#,##0")&" kg – about "&TEXT(Inventory!Q14,"#,##0")&" kg extra. Fill rate is still "&TEXT(Inventory!S14,"0%")&"." -> Average stock held is 1,670 kg against a target of 720 kg – about 950 kg extra. Fill rate is still 100%. | D10: Order smaller batches more often, especially for fast-spoiling Tomato, Cucumber and Capsicum. Keep the safety stock, but remove the extra buffer. | E10: ="Waste cut by "&TEXT(Waste!B3,"0%")&" saves about "&TEXT(Waste!J14,"#,##0")&" kg (≈ ₹"&TEXT(Waste!K14,"#,##0")&" at assumed prices)." -> Waste cut by 50% saves about 878 kg (≈ ₹24,777 at assumed prices).
A11: 7 | B11: How to reduce waste? | C11: ="Tomato, Cucumber and Capsicum lose "&TEXT(Waste!C9+Waste!C12+Waste!C13,"#,##0")&" kg together ("&TEXT((Waste!C9+Waste!C12+Waste!C13)/Waste!C14,"0%")&" of all waste)." -> Tomato, Cucumber and Capsicum lose 809 kg together (46% of all waste). | D11: Send near-expiry stock to cut / chopped and ready-to-use products (Fambo's value-added line) or offer a quick sale to HoReCa customers before it spoils. | E11: Turns waste into sales.
A12: 8 | B12: Next steps | C12: All values in this project are simulated. Shelf life, buying price, supplier on-time delivery and customer order data are not available. | D12: With real data: add shelf life per product, supplier on-time %, price per kg and customer-wise orders; then recalculate service level, costs and savings. | E12: Moves the model from practice to real decisions.

Sheet Data
A1: Date | B1: Product | C1: Opening Stock (kg) | D1: Demand (kg) | E1: Received (kg) | F1: Closing Stock (kg) | G1: Lead Time (days) | H1: Avg Daily Demand (kg) | I1: Safety Stock (kg) | J1: Reorder Point (kg) | K1: Expiry/Waste (kg) | L1: Fill Rate | M1: Waste % of Demand | N1: Days of Cover | O1: Below Reorder Pt (1=yes) | P1: Stockout (1=yes)
A2: 46266 | B2: Tomato | C2: 450 | D2: 48 | E2: 0 | F2: =C2+E2-D2-K2 -> 322 | G2: 3 | H2: 58 | I2: 50 | J2: 224 | K2: 80 | L2: =IF(D2>0,MIN(1,(C2+E2)/D2),1) -> 1 | M2: =IF(D2>0,K2/D2,0) -> 1.6666667 | N2: =IF(H2>0,F2/H2,0) -> 5.5517241 | O2: =IF(F2<J2,1,0) -> 0 | P2: =IF(C2+E2<D2,1,0) -> 0
A3: 46266 | B3: Onion | C3: 650 | D3: 80 | E3: 0 | F3: =C3+E3-D3-K3 -> 484 | G3: 4 | H3: 72 | I3: 72 | J3: 360 | K3: 86 | L3: =IF(D3>0,MIN(1,(C3+E3)/D3),1) -> 1 | M3: =IF(D3>0,K3/D3,0) -> 1.075 | N3: =IF(H3>0,F3/H3,0) -> 6.7222222 | O3: =IF(F3<J3,1,0) -> 0 | P3: =IF(C3+E3<D3,1,0) -> 0
A4: 46266 | B4: Potato | C4: 700 | D4: 74 | E4: 0 | F4: =C4+E4-D4-K4 -> 551 | G4: 4 | H4: 80 | I4: 80 | J4: 400 | K4: 75 | L4: =IF(D4>0,MIN(1,(C4+E4)/D4),1) -> 1 | M4: =IF(D4>0,K4/D4,0) -> 1.0135135 | N4: =IF(H4>0,F4/H4,0) -> 6.8875 | O4: =IF(F4<J4,1,0) -> 0 | P4: =IF(C4+E4<D4,1,0) -> 0
A5: 46266 | B5: Cucumber | C5: 300 | D5: 32 | E5: 0 | F5: =C5+E5-D5-K5 -> 201 | G5: 2 | H5: 38 | I5: 27 | J5: 103 | K5: 67 | L5: =IF(D5>0,MIN(1,(C5+E5)/D5),1) -> 1 | M5: =IF(D5>0,K5/D5,0) -> 2.09375 | N5: =IF(H5>0,F5/H5,0) -> 5.2894737 | O5: =IF(F5<J5,1,0) -> 0 | P5: =IF(C5+E5<D5,1,0) -> 0
A6: 46266 | B6: Capsicum | C6: 250 | D6: 30 | E6: 0 | F6: =C6+E6-D6-K6 -> 176 | G6: 3 | H6: 30 | I6: 26 | J6: 116 | K6: 44 | L6: =IF(D6>0,MIN(1,(C6+E6)/D6),1) -> 1 | M6: =IF(D6>0,K6/D6,0) -> 1.4666667 | N6: =IF(H6>0,F6/H6,0) -> 5.8666667 | O6: =IF(F6<J6,1,0) -> 0 | P6: =IF(C6+E6<D6,1,0) -> 0
A7: 46267 | B7: Tomato | C7: 322 | D7: 59 | E7: 0 | F7: =C7+E7-D7-K7 -> 263 | G7: 3 | H7: 48 | I7: 42 | J7: 186 | K7: 0 | L7: =IF(D7>0,MIN(1,(C7+E7)/D7),1) -> 1 | M7: =IF(D7>0,K7/D7,0) -> 0 | N7: =IF(H7>0,F7/H7,0) -> 5.4791667 | O7: =IF(F7<J7,1,0) -> 0 | P7: =IF(C7+E7<D7,1,0) -> 0
A8: 46267 | B8: Onion | C8: 484 | D8: 73 | E8: 0 | F8: =C8+E8-D8-K8 -> 411 | G8: 4 | H8: 80 | I8: 80 | J8: 400 | K8: 0 | L8: =IF(D8>0,MIN(1,(C8+E8)/D8),1) -> 1 | M8: =IF(D8>0,K8/D8,0) -> 0 | N8: =IF(H8>0,F8/H8,0) -> 5.1375 | O8: =IF(F8<J8,1,0) -> 0 | P8: =IF(C8+E8<D8,1,0) -> 0
A9: 46267 | B9: Potato | C9: 551 | D9: 80 | E9: 0 | F9: =C9+E9-D9-K9 -> 471 | G9: 4 | H9: 74 | I9: 74 | J9: 370 | K9: 0 | L9: =IF(D9>0,MIN(1,(C9+E9)/D9),1) -> 1 | M9: =IF(D9>0,K9/D9,0) -> 0 | N9: =IF(H9>0,F9/H9,0) -> 6.3648649 | O9: =IF(F9<J9,1,0) -> 0 | P9: =IF(C9+E9<D9,1,0) -> 0
A10: 46267 | B10: Cucumber | C10: 201 | D10: 33 | E10: 0 | F10: =C10+E10-D10-K10 -> 168 | G10: 2 | H10: 32 | I10: 23 | J10: 87 | K10: 0 | L10: =IF(D10>0,MIN(1,(C10+E10)/D10),1) -> 1 | M10: =IF(D10>0,K10/D10,0) -> 0 | N10: =IF(H10>0,F10/H10,0) -> 5.25 | O10: =IF(F10<J10,1,0) -> 0 | P10: =IF(C10+E10<D10,1,0) -> 0
A11: 46267 | B11: Capsicum | C11: 176 | D11: 26 | E11: 0 | F11: =C11+E11-D11-K11 -> 150 | G11: 3 | H11: 30 | I11: 26 | J11: 116 | K11: 0 | L11: =IF(D11>0,MIN(1,(C11+E11)/D11),1) -> 1 | M11: =IF(D11>0,K11/D11,0) -> 0 | N11: =IF(H11>0,F11/H11,0) -> 5 | O11: =IF(F11<J11,1,0) -> 0 | P11: =IF(C11+E11<D11,1,0) -> 0
A12: 46268 | B12: Tomato | C12: 263 | D12: 66 | E12: 0 | F12: =C12+E12-D12-K12 -> 197 | G12: 3 | H12: 53.5 | I12: 46 | J12: 206 | K12: 0 | L12: =IF(D12>0,MIN(1,(C12+E12)/D12),1) -> 1 | M12: =IF(D12>0,K12/D12,0) -> 0 | N12: =IF(H12>0,F12/H12,0) -> 3.682243 | O12: =IF(F12<J12,1,0) -> 1 | P12: =IF(C12+E12<D12,1,0) -> 0
A13: 46268 | B13: Onion | C13: 411 | D13: 66 | E13: 0 | F13: =C13+E13-D13-K13 -> 345 | G13: 4 | H13: 76.5 | I13: 76 | J13: 382 | K13: 0 | L13: =IF(D13>0,MIN(1,(C13+E13)/D13),1) -> 1 | M13: =IF(D13>0,K13/D13,0) -> 0 | N13: =IF(H13>0,F13/H13,0) -> 4.5098039 | O13: =IF(F13<J13,1,0) -> 1 | P13: =IF(C13+E13<D13,1,0) -> 0
... A151: 46295 | B151: Capsicum | C151: 116 | D151: 29 | E151: 0 | F151: =C151+E151-D151-K151 -> 87 | G151: 3 | H151: 28.9 | I151: 25 | J151: 112 | K151: 0 | L151: =IF(D151>0,MIN(1,(C151+E151)/D151),1) -> 1 | M151: =IF(D151>0,K151/D151,0) -> 0 | N151: =IF(H151>0,F151/H151,0) -> 3.0103806 | O151: =IF(F151<J151,1,0) -> 1 | P151: =IF(C151+E151<D151,1,0) -> 0

Sheet ReadMe
A1: ReadMe · How this workbook works
A2: Please read before using the numbers.
A4: Purpose | B4: Answer 3 questions for a fresh-produce supply chain business: What to order? When to order? How to reduce waste?
A5: Data status | B5: All data is SIMULATED (30 days, 5 products: Tomato, Onion, Potato, Cucumber, Capsicum). It is not Fambo data and not actual company results. Built as a practice project for the Fambo Innovation Supply Chain internship application.
A6: Sheets | B6: Dashboard – KPIs, charts, scorecard | Demand – forecast | Inventory – safety stock & reorder point | Waste – expiry analysis | Recommendations – actions | Data – source data + added columns.
A7: Demand forecast | B7: Forecast for a day = average of the previous 7 days. Forecast error (MAPE) is tested on days 8–30. Future days use the latest 7-day average (flat line).
A8: Safety stock | B8: Z × standard deviation of daily demand × √lead time. Z comes from the service level (95% → 1.65). The source file used a simpler rule (0.5 × avg demand × √lead time); both are shown for comparison.
A9: Reorder point | B9: Average daily demand × lead time + safety stock. Stock status: ORDER NOW (below ROP), WATCH (within 20% above ROP), OK.
A10: Order quantity | B10: Average daily demand × order cycle days (default 4), rounded up to the next 10 kg. Target average stock = safety stock + half an order.
A11: Fill rate | B11: Share of demand served = MIN(1, (opening + received) ÷ demand). Closing stock = opening + received − demand − waste.
A12: Waste value | B12: Uses ASSUMED prices (₹/kg) typed in the yellow cells of the Waste sheet. Replace them with real buying rates.
A13: Colour guide | B13: Yellow cell with blue text = input you can change. Everything else is a formula.
A14: Limitations | B14: Small, simulated dataset; no seasonality, price, shelf-life or supplier data. Results show the method, not real business performance.
A15: Interview talking points | B15: How I would validate data · how to track FEFO/expiry · how waste % and fill rate are measured · why high waste with 100% fill rate means over-stocking · how I would review reorder parameters with operations.
